Workbook
Name Slicer_Representative: #N/A

Sheet Customer Center Dashboard
P18: R01 | Q18: R02 | R18: R03 | S18: R04 | T18: R05 | U18: Total
O19: =Pivot!A71 -> Cincinnati
O20: =Pivot!A72 -> C0003 | P20: =Pivot!B72 -> 891 | Q20: =Pivot!C72 -> 1332 | R20: =Pivot!D72 -> 1282 | S20: =Pivot!E72 -> 739 | T20: =Pivot!F72 -> 560 | U20: =Pivot!G72 -> 4804
O21: =Pivot!A73 -> C0004 | P21: =Pivot!B73 -> 1991 | Q21: =Pivot!C73 -> 1886 | R21: =Pivot!D73 -> 1206 | S21: =Pivot!E73 -> 884 | T21: =Pivot!F73 -> 1722 | U21: =Pivot!G73 -> 7689
O22: =Pivot!A74 -> C0011 | P22: =Pivot!B74 -> 1163 | Q22: =Pivot!C74 -> 1180 | R22: =Pivot!D74 -> 1616 | S22: =Pivot!E74 -> 1043 | T22: =Pivot!F74 -> 1747 | U22: =Pivot!G74 -> 6749
O23: =Pivot!A75 -> C0012 | P23: =Pivot!B75 -> 1438 | Q23: =Pivot!C75 -> 1616 | R23: =Pivot!D75 -> 866 | S23: =Pivot!E75 -> 829 | T23: =Pivot!F75 -> 2070 | U23: =Pivot!G75 -> 6819
O24: =Pivot!A76 -> Cleveland
O25: =Pivot!A77 -> C0002 | P25: =Pivot!B77 -> 1233 | Q25: =Pivot!C77 -> 223 | R25: =Pivot!D77 -> 1680 | S25: =Pivot!E77 -> 990 | T25: =Pivot!F77 -> 1508 | U25: =Pivot!G77 -> 5634
O26: =Pivot!A78 -> C0007 | P26: =Pivot!B78 -> 1598 | Q26: =Pivot!C78 -> 1907 | R26: =Pivot!D78 -> 869 | S26: =Pivot!E78 -> 1426 | T26: =Pivot!F78 -> 1416 | U26: =Pivot!G78 -> 7216
O27: =Pivot!A79 -> C0008 | P27: =Pivot!B79 -> 900 | Q27: =Pivot!C79 -> 1016 | R27: =Pivot!D79 -> 960 | S27: =Pivot!E79 -> 940 | T27: =Pivot!F79 -> 1193 | U27: =Pivot!G79 -> 5009
O28: =Pivot!A80 -> C0010 | P28: =Pivot!B80 -> 900 | Q28: =Pivot!C80 -> 1470 | R28: =Pivot!D80 -> 1617 | S28: =Pivot!E80 -> 1314 | T28: =Pivot!F80 -> 941 | U28: =Pivot!G80 -> 6242
O29: =Pivot!A81 -> C0013 | P29: =Pivot!B81 -> 1255 | Q29: =Pivot!C81 -> 516 | R29: =Pivot!D81 -> 1874 | S29: =Pivot!E81 -> 1863 | T29: =Pivot!F81 -> 1722 | U29: =Pivot!G81 -> 7230
O30: =Pivot!A82 -> C0015 | P30: =Pivot!B82 -> 1138 | Q30: =Pivot!C82 -> 1898 | R30: =Pivot!D82 -> 1482 | S30: =Pivot!E82 -> 846 | T30: =Pivot!F82 -> 1154 | U30: =Pivot!G82 -> 6518
O31: =Pivot!A83 -> Columbus
O32: =Pivot!A84 -> C0001 | P32: =Pivot!B84 -> 1655 | Q32: =Pivot!C84 -> 805 | R32: =Pivot!D84 -> 2263 | S32: =Pivot!E84 -> 987 | T32: =Pivot!F84 -> 1075 | U32: =Pivot!G84 -> 6785
O33: =Pivot!A85 -> C0005 | P33: =Pivot!B85 -> 1104 | Q33: =Pivot!C85 -> 2280 | R33: =Pivot!D85 -> 1445 | S33: =Pivot!E85 -> 1722 | T33: =Pivot!F85 -> 1196 | U33: =Pivot!G85 -> 7747
O34: =Pivot!A86 -> C0006 | P34: =Pivot!B86 -> 372 | Q34: =Pivot!C86 -> 1818 | R34: =Pivot!D86 -> 1346 | S34: =Pivot!E86 -> 1156 | T34: =Pivot!F86 -> 1484 | U34: =Pivot!G86 -> 6176
O35: =Pivot!A87 -> C0009 | P35: =Pivot!B87 -> 1415 | Q35: =Pivot!C87 -> 1271 | R35: =Pivot!D87 -> 1214 | S35: =Pivot!E87 -> 1135 | T35: =Pivot!F87 -> 1566 | U35: =Pivot!G87 -> 6601
O36: =Pivot!A88 -> C0014 | P36: =Pivot!B88 -> 1362 | Q36: =Pivot!C88 -> 1363 | R36: =Pivot!D88 -> 1152 | S36: =Pivot!E88 -> 777 | T36: =Pivot!F88 -> 750 | U36: =Pivot!G88 -> 5404

Sheet Pivot
A3: Call count | B3: Total Amount | C3: Total Duration | D3: Average Rating | E3: 5* calls
A4: 1000 | B4: 96623 | C4: 89850 | D4: 3.8854 | E4: 307
A9: Call count | B9: Total Amount | C9: Total Duration | D9: Average Rating | E9: 5* calls
A10: 1000 | B10: 96623 | C10: 89850 | D10: 3.8854 | E10: 307
A16: Row Labels | B16: Call count | C16: Call count2
A17: Jan | B17: 79 | C17: 79
A18: Feb | B18: 66 | C18: 66
A19: Mar | B19: 155 | C19: 155
A20: Apr | B20: 136 | C20: 136
A21: May | B21: 83 | C21: 83
A22: Jun | B22: 67 | C22: 67
A23: Jul | B23: 64 | C23: 64
A24: Aug | B24: 50 | C24: 50
A25: Sep | B25: 76 | C25: 76
A26: Oct | B26: 114 | C26: 114
A27: Nov | B27: 57 | C27: 57
A28: Dec | B28: 53 | C28: 53
A29: Grand Total | B29: 1000 | C29: 1000
A32: Row Labels | B32: Call count
A33: Sunday | B33: 146
A34: Saturday | B34: 161
A35: Friday | B35: 141
A36: Thursday | B36: 128
A37: Wednesday | B37: 153
A38: Tuesday | B38: 138
A39: Monday | B39: 133
A40: Grand Total | B40: 1000
A43: Row Labels | B43: Sum of Purchase Amount | H43: Row Labels | I43: Call count
A44: R05 | B44: 20104 | H44: R05 | I44: 200
A45: R04 | B45: 16651 | H45: R04 | I45: 186
A46: R03 | B46: 20872 | H46: R03 | I46: 207
A47: R02 | B47: 20581 | H47: R02 | I47: 218
A48: R01 | B48: 18415 | H48: R01 | I48: 189
A49: Grand Total | B49: 96623 | H49: Grand Total | I49: 1000
A53: Call count | B53: Column Labels
A54: Row Labels | B54: Female | C54: Male | D54: Grand Total
A55: Cincinnati | B55: 144 | C55: 132 | D55: 276
A56: Cleveland | B56: 326 | C56: 63 | D56: 389
A57: Columbus | B57: 129 | C57: 206 | D57: 335
A58: Grand Total | B58: 599 | C58: 401 | D58: 1000
...

Sheet Data
A1: Call number | B1: Customer ID | C1: Duration | D1: Representative | E1: Date of Call | F1: Purchase Amount | G1: Satisfaction Rating | H1: FY | I1: Day of week | J1: Duration Bucket | K1: Rating rounded | M1: Customer ID | N1: Gedner | O1: Age | P1: City
A2: Call_7271 | B2: C0003 | C2: 116 | D2: R05 | E2: 44927 | F2: 128 | G2: 4.9 | H2: =IF(MONTH(calls[[#This Row],[Date of Call]])<=6, YEAR(calls[[#This Row],[Date of Call]]), YEAR(calls[[#This Row],[Date of Call]])+1) -> 2023 | I2: =TEXT(calls[[#This Row],[Date of Call]],"DDDD") -> Sunday | J2: {=_xlfn.IFS(calls[[#This Row],[Duration]]<=10,"Under 10 mins", calls[[#This Row],[Duration]]<=30, "10 to 30 mins", calls[[#This Row],[Duration]]<=60, "30 to 60 mins", calls[[#This Row],[Duration]]<=120, "1 to 2 hours", TRUE, "More than 2 hours")} -> 1 to 2 hours | K2: =ROUND(calls[[#This Row],[Satisfaction Rating]],0) -> 5 | M2: C0001 | N2: Male | O2: 41 | P2: Columbus
A3: Call_7272 | B3: C0004 | C3: 119 | D3: R05 | E3: 44927 | F3: 135 | G3: 2.9 | H3: =IF(MONTH(calls[[#This Row],[Date of Call]])<=6, YEAR(calls[[#This Row],[Date of Call]]), YEAR(calls[[#This Row],[Date of Call]])+1) -> 2023 | I3: =TEXT(calls[[#This Row],[Date of Call]],"DDDD") -> Sunday | J3: {=_xlfn.IFS(calls[[#This Row],[Duration]]<=10,"Under 10 mins", calls[[#This Row],[Duration]]<=30, "10 to 30 mins", calls[[#This Row],[Duration]]<=60, "30 to 60 mins", calls[[#This Row],[Duration]]<=120, "1 to 2 hours", TRUE, "More than 2 hours")} -> 1 to 2 hours | K3: =ROUND(calls[[#This Row],[Satisfaction Rating]],0) -> 3 | M3: C0002 | N3: Male | O3: 31 | P3: Cleveland
A4: Call_7273 | B4: C0005 | C4: 68 | D4: R02 | E4: 44927 | F4: 66 | G4: 4.7 | H4: =IF(MONTH(calls[[#This Row],[Date of Call]])<=6, YEAR(calls[[#This Row],[Date of Call]]), YEAR(calls[[#This Row],[Date of Call]])+1) -> 2023 | I4: =TEXT(calls[[#This Row],[Date of Call]],"DDDD") -> Sunday | J4: {=_xlfn.IFS(calls[[#This Row],[Duration]]<=10,"Under 10 mins", calls[[#This Row],[Duration]]<=30, "10 to 30 mins", calls[[#This Row],[Duration]]<=60, "30 to 60 mins", calls[[#This Row],[Duration]]<=120, "1 to 2 hours", TRUE, "More than 2 hours")} -> 1 to 2 hours | K4: =ROUND(calls[[#This Row],[Satisfaction Rating]],0) -> 5 | M4: C0003 | N4: Male | O4: 26 | P4: Cincinnati
A5: Call_7274 | B5: C0014 | C5: 119 | D5: R02 | E5: 44927 | F5: 22 | G5: 2.9 | H5: =IF(MONTH(calls[[#This Row],[Date of Call]])<=6, YEAR(calls[[#This Row],[Date of Call]]), YEAR(calls[[#This Row],[Date of Call]])+1) -> 2023 | I5: =TEXT(calls[[#This Row],[Date of Call]],"DDDD") -> Sunday | J5: {=_xlfn.IFS(calls[[#This Row],[Duration]]<=10,"Under 10 mins", calls[[#This Row],[Duration]]<=30, "10 to 30 mins", calls[[#This Row],[Duration]]<=60, "30 to 60 mins", calls[[#This Row],[Duration]]<=120, "1 to 2 hours", TRUE, "More than 2 hours")} -> 1 to 2 hours | K5: =ROUND(calls[[#This Row],[Satisfaction Rating]],0) -> 3 | M5: C0004 | N5: Male | O5: 36 | P5: Cincinnati
A6: Call_7275 | B6: C0011 | C6: 128 | D6: R01 | E6: 44928 | F6: 31 | G6: 2.8 | H6: =IF(MONTH(calls[[#This Row],[Date of Call]])<=6, YEAR(calls[[#This Row],[Date of Call]]), YEAR(calls[[#This Row],[Date of Call]])+1) -> 2023 | I6: =TEXT(calls[[#This Row],[Date of Call]],"DDDD") -> Monday | J6: {=_xlfn.IFS(calls[[#This Row],[Duration]]<=10,"Under 10 mins", calls[[#This Row],[Duration]]<=30, "10 to 30 mins", calls[[#This Row],[Duration]]<=60, "30 to 60 mins", calls[[#This Row],[Duration]]<=120, "1 to 2 hours", TRUE, "More than 2 hours")} -> More than 2 hours | K6: =ROUND(calls[[#This Row],[Satisfaction Rating]],0) -> 3 | M6: C0005 | N6: Male | O6: 37 | P6: Columbus
A7: Call_7276 | B7: C0011 | C7: 49 | D7: R02 | E7: 44929 | F7: 135 | G7: 4.8 | H7: =IF(MONTH(calls[[#This Row],[Date of Call]])<=6, YEAR(calls[[#This Row],[Date of Call]]), YEAR(calls[[#This Row],[Date of Call]])+1) -> 2023 | I7: =TEXT(calls[[#This Row],[Date of Call]],"DDDD") -> Tuesday | J7: {=_xlfn.IFS(calls[[#This Row],[Duration]]<=10,"Under 10 mins", calls[[#This Row],[Duration]]<=30, "10 to 30 mins", calls[[#This Row],[Duration]]<=60, "30 to 60 mins", calls[[#This Row],[Duration]]<=120, "1 to 2 hours", TRUE, "More than 2 hours")} -> 30 to 60 mins | K7: =ROUND(calls[[#This Row],[Satisfaction Rating]],0) -> 5 | M7: C0006 | N7: Male | O7: 23 | P7: Columbus
A8: Call_7277 | B8: C0007 | C8: 84 | D8: R05 | E8: 44929 | F8: 60 | G8: 4.7 | H8: =IF(MONTH(calls[[#This Row],[Date of Call]])<=6, YEAR(calls[[#This Row],[Date of Call]]), YEAR(calls[[#This Row],[Date of Call]])+1) -> 2023 | I8: =TEXT(calls[[#This Row],[Date of Call]],"DDDD") -> Tuesday | J8: {=_xlfn.IFS(calls[[#This Row],[Duration]]<=10,"Under 10 mins", calls[[#This Row],[Duration]]<=30, "10 to 30 mins", calls[[#This Row],[Duration]]<=60, "30 to 60 mins", calls[[#This Row],[Duration]]<=120, "1 to 2 hours", TRUE, "More than 2 hours")} -> 1 to 2 hours | K8: =ROUND(calls[[#This Row],[Satisfaction Rating]],0) -> 5 | M8: C0007 | N8: Female | O8: 22 | P8: Cleveland
A9: Call_7278 | B9: C0003 | C9: 103 | D9: R04 | E9: 44929 | F9: 148 | G9: 4.4 | H9: =IF(MONTH(calls[[#This Row],[Date of Call]])<=6, YEAR(calls[[#This Row],[Date of Call]]), YEAR(calls[[#This Row],[Date of Call]])+1) -> 2023 | I9: =TEXT(calls[[#This Row],[Date of Call]],"DDDD") -> Tuesday | J9: {=_xlfn.IFS(calls[[#This Row],[Duration]]<=10,"Under 10 mins", calls[[#This Row],[Duration]]<=30, "10 to 30 mins", calls[[#This Row],[Duration]]<=60, "30 to 60 mins", calls[[#This Row],[Duration]]<=120, "1 to 2 hours", TRUE, "More than 2 hours")} -> 1 to 2 hours | K9: =ROUND(calls[[#This Row],[Satisfaction Rating]],0) -> 4 | M9: C0008 | N9: Female | O9: 42 | P9: Cleveland
A10: Call_7279 | B10: C0005 | C10: 31 | D10: R02 | E10: 44929 | F10: 135 | G10: 3.6 | H10: =IF(MONTH(calls[[#This Row],[Date of Call]])<=6, YEAR(calls[[#This Row],[Date of Call]]), YEAR(calls[[#This Row],[Date of Call]])+1) -> 2023 | I10: =TEXT(calls[[#This Row],[Date of Call]],"DDDD") -> Tuesday | J10: {=_xlfn.IFS(calls[[#This Row],[Duration]]<=10,"Under 10 mins", calls[[#This Row],[Duration]]<=30, "10 to 30 mins", calls[[#This Row],[Duration]]<=60, "30 to 60 mins", calls[[#This Row],[Duration]]<=120, "1 to 2 hours", TRUE, "More than 2 hours")} -> 30 to 60 mins | K10: =ROUND(calls[[#This Row],[Satisfaction Rating]],0) -> 4 | M10: C0009 | N10: Female | O10: 25 | P10: Columbus
A11: Call_7280 | B11: C0010 | C11: 44 | D11: R03 | E11: 44929 | F11: 105 | G11: 2.9 | H11: =IF(MONTH(calls[[#This Row],[Date of Call]])<=6, YEAR(calls[[#This Row],[Date of Call]]), YEAR(calls[[#This Row],[Date of Call]])+1) -> 2023 | I11: =TEXT(calls[[#This Row],[Date of Call]],"DDDD") -> Tuesday | J11: {=_xlfn.IFS(calls[[#This Row],[Duration]]<=10,"Under 10 mins", calls[[#This Row],[Duration]]<=30, "10 to 30 mins", calls[[#This Row],[Duration]]<=60, "30 to 60 mins", calls[[#This Row],[Duration]]<=120, "1 to 2 hours", TRUE, "More than 2 hours")} -> 30 to 60 mins | K11: =ROUND(calls[[#This Row],[Satisfaction Rating]],0) -> 3 | M11: C0010 | N11: Female | O11: 30 | P11: Cleveland
A12: Call_7281 | B12: C0011 | C12: 102 | D12: R02 | E12: 44929 | F12: 69 | G12: 4.9 | H12: =IF(MONTH(calls[[#This Row],[Date of Call]])<=6, YEAR(calls[[#This Row],[Date of Call]]), YEAR(calls[[#This Row],[Date of Call]])+1) -> 2023 | I12: =TEXT(calls[[#This Row],[Date of Call]],"DDDD") -> Tuesday | J12: {=_xlfn.IFS(calls[[#This Row],[Duration]]<=10,"Under 10 mins", calls[[#This Row],[Duration]]<=30, "10 to 30 mins", calls[[#This Row],[Duration]]<=60, "30 to 60 mins", calls[[#This Row],[Duration]]<=120, "1 to 2 hours", TRUE, "More than 2 hours")} -> 1 to 2 hours | K12: =ROUND(calls[[#This Row],[Satisfaction Rating]],0) -> 5 | M12: C0011 | N12: Female | O12: 30 | P12: Cincinnati
A13: Call_7282 | B13: C0013 | C13: 135 | D13: R05 | E13: 44929 | F13: 46 | G13: 3.4 | H13: =IF(MONTH(calls[[#This Row],[Date of Call]])<=6, YEAR(calls[[#This Row],[Date of Call]]), YEAR(calls[[#This Row],[Date of Call]])+1) -> 2023 | I13: =TEXT(calls[[#This Row],[Date of Call]],"DDDD") -> Tuesday | J13: {=_xlfn.IFS(calls[[#This Row],[Duration]]<=10,"Under 10 mins", calls[[#This Row],[Duration]]<=30, "10 to 30 mins", calls[[#This Row],[Duration]]<=60, "30 to 60 mins", calls[[#This Row],[Duration]]<=120, "1 to 2 hours", TRUE, "More than 2 hours")} -> More than 2 hours | K13: =ROUND(calls[[#This Row],[Satisfaction Rating]],0) -> 3 | M13: C0012 | N13: Female | O13: 28 | P13: Cincinnati
... A16: Call_7285 | B16: C0013 | C16: 48 | D16: R01 | E16: 44930 | F16: 68 | G16: 4.9 | H16: =IF(MONTH(calls[[#This Row],[Date of Call]])<=6, YEAR(calls[[#This Row],[Date of Call]]), YEAR(calls[[#This Row],[Date of Call]])+1) -> 2023 | I16: =TEXT(calls[[#This Row],[Date of Call]],"DDDD") -> Wednesday | J16: {=_xlfn.IFS(calls[[#This Row],[Duration]]<=10,"Under 10 mins", calls[[#This Row],[Duration]]<=30, "10 to 30 mins", calls[[#This Row],[Duration]]<=60, "30 to 60 mins", calls[[#This Row],[Duration]]<=120, "1 to 2 hours", TRUE, "More than 2 hours")} -> 30 to 60 mins | K16: =ROUND(calls[[#This Row],[Satisfaction Rating]],0) -> 5 | M16: C0015 | N16: Female | O16: 43 | P16: Cleveland
A17: Call_7286 | B17: C0010 | C17: 176 | D17: R05 | E17: 44931 | F17: 24 | G17: 4.8 | H17: =IF(MONTH(calls[[#This Row],[Date of Call]])<=6, YEAR(calls[[#This Row],[Date of Call]]), YEAR(calls[[#This Row],[Date of Call]])+1) -> 2023 | I17: =TEXT(calls[[#This Row],[Date of Call]],"DDDD") -> Thursday | J17: {=_xlfn.IFS(calls[[#This Row],[Duration]]<=10,"Under 10 mins", calls[[#This Row],[Duration]]<=30, "10 to 30 mins", calls[[#This Row],[Duration]]<=60, "30 to 60 mins", calls[[#This Row],[Duration]]<=120, "1 to 2 hours", TRUE, "More than 2 hours")} -> More than 2 hours | K17: =ROUND(calls[[#This Row],[Satisfaction Rating]],0) -> 5
A18: Call_7287 | B18: C0010 | C18: 99 | D18: R01 | E18: 44931 | F18: 195 | G18: 3.9 | H18: =IF(MONTH(calls[[#This Row],[Date of Call]])<=6, YEAR(calls[[#This Row],[Date of Call]]), YEAR(calls[[#This Row],[Date of Call]])+1) -> 2023 | I18: =TEXT(calls[[#This Row],[Date of Call]],"DDDD") -> Thursday | J18: {=_xlfn.IFS(calls[[#This Row],[Duration]]<=10,"Under 10 mins", calls[[#This Row],[Duration]]<=30, "10 to 30 mins", calls[[#This Row],[Duration]]<=60, "30 to 60 mins", calls[[#This Row],[Duration]]<=120, "1 to 2 hours", TRUE, "More than 2 hours")} -> 1 to 2 hours | K18: =ROUND(calls[[#This Row],[Satisfaction Rating]],0) -> 4
A19: Call_7288 | B19: C0009 | C19: 28 | D19: R03 | E19: 44931 | F19: 28 | G19: 3.8 | H19: =IF(MONTH(calls[[#This Row],[Date of Call]])<=6, YEAR(calls[[#This Row],[Date of Call]]), YEAR(calls[[#This Row],[Date of Call]])+1) -> 2023 | I19: =TEXT(calls[[#This Row],[Date of Call]],"DDDD") -> Thursday | J19: {=_xlfn.IFS(calls[[#This Row],[Duration]]<=10,"Under 10 mins", calls[[#This Row],[Duration]]<=30, "10 to 30 mins", calls[[#This Row],[Duration]]<=60, "30 to 60 mins", calls[[#This Row],[Duration]]<=120, "1 to 2 hours", TRUE, "More than 2 hours")} -> 10 to 30 mins | K19: =ROUND(calls[[#This Row],[Satisfaction Rating]],0) -> 4
A20: Call_7289 | B20: C0007 | C20: 54 | D20: R02 | E20: 44931 | F20: 170 | G20: 4.3 | H20: =IF(MONTH(calls[[#This Row],[Date of Call]])<=6, YEAR(calls[[#This Row],[Date of Call]]), YEAR(calls[[#This Row],[Date of Call]])+1) -> 2023 | I20: =TEXT(calls[[#This Row],[Date of Call]],"DDDD") -> Thursday | J20: {=_xlfn.IFS(calls[[#This Row],[Duration]]<=10,"Under 10 mins", calls[[#This Row],[Duration]]<=30, "10 to 30 mins", calls[[#This Row],[Duration]]<=60, "30 to 60 mins", calls[[#This Row],[Duration]]<=120, "1 to 2 hours", TRUE, "More than 2 hours")} -> 30 to 60 mins | K20: =ROUND(calls[[#This Row],[Satisfaction Rating]],0) -> 4
A21: Call_7290 | B21: C0006 | C21: 48 | D21: R05 | E21: 44932 | F21: 30 | G21: 4.4 | H21: =IF(MONTH(calls[[#This Row],[Date of Call]])<=6, YEAR(calls[[#This Row],[Date of Call]]), YEAR(calls[[#This Row],[Date of Call]])+1) -> 2023 | I21: =TEXT(calls[[#This Row],[Date of Call]],"DDDD") -> Friday | J21: {=_xlfn.IFS(calls[[#This Row],[Duration]]<=10,"Under 10 mins", calls[[#This Row],[Duration]]<=30, "10 to 30 mins", calls[[#This Row],[Duration]]<=60, "30 to 60 mins", calls[[#This Row],[Duration]]<=120, "1 to 2 hours", TRUE, "More than 2 hours")} -> 30 to 60 mins | K21: =ROUND(calls[[#This Row],[Satisfaction Rating]],0) -> 4
A22: Call_7291 | B22: C0004 | C22: 128 | D22: R05 | E22: 44932 | F22: 72 | G22: 5 | H22: =IF(MONTH(calls[[#This Row],[Date of Call]])<=6, YEAR(calls[[#This Row],[Date of Call]]), YEAR(calls[[#This Row],[Date of Call]])+1) -> 2023 | I22: =TEXT(calls[[#This Row],[Date of Call]],"DDDD") -> Friday | J22: {=_xlfn.IFS(calls[[#This Row],[Duration]]<=10,"Under 10 mins", calls[[#This Row],[Duration]]<=30, "10 to 30 mins", calls[[#This Row],[Duration]]<=60, "30 to 60 mins", calls[[#This Row],[Duration]]<=120, "1 to 2 hours", TRUE, "More than 2 hours")} -> More than 2 hours | K22: =ROUND(calls[[#This Row],[Satisfaction Rating]],0) -> 5
A23: Call_7292 | B23: C0004 | C23: 38 | D23: R04 | E23: 44933 | F23: 92 | G23: 4.9 | H23: =IF(MONTH(calls[[#This Row],[Date of Call]])<=6, YEAR(calls[[#This Row],[Date of Call]]), YEAR(calls[[#This Row],[Date of Call]])+1) -> 2023 | I23: =TEXT(calls[[#This Row],[Date of Call]],"DDDD") -> Saturday | J23: {=_xlfn.IFS(calls[[#This Row],[Duration]]<=10,"Under 10 mins", calls[[#This Row],[Duration]]<=30, "10 to 30 mins", calls[[#This Row],[Duration]]<=60, "30 to 60 mins", calls[[#This Row],[Duration]]<=120, "1 to 2 hours", TRUE, "More than 2 hours")} -> 30 to 60 mins | K23: =ROUND(calls[[#This Row],[Satisfaction Rating]],0) -> 5
A24: Call_7293 | B24: C0003 | C24: 67 | D24: R04 | E24: 44934 | F24: 165 | G24: 4.5 | H24: =IF(MONTH(calls[[#This Row],[Date of Call]])<=6, YEAR(calls[[#This Row],[Date of Call]]), YEAR(calls[[#This Row],[Date of Call]])+1) -> 2023 | I24: =TEXT(calls[[#This Row],[Date of Call]],"DDDD") -> Sunday | J24: {=_xlfn.IFS(calls[[#This Row],[Duration]]<=10,"Under 10 mins", calls[[#This Row],[Duration]]<=30, "10 to 30 mins", calls[[#This Row],[Duration]]<=60, "30 to 60 mins", calls[[#This Row],[Duration]]<=120, "1 to 2 hours", TRUE, "More than 2 hours")} -> 1 to 2 hours | K24: =ROUND(calls[[#This Row],[Satisfaction Rating]],0) -> 5
A25: Call_7294 | B25: C0015 | C25: 58 | D25: R02 | E25: 44934 | F25: 140 | G25: 2.1 | H25: =IF(MONTH(calls[[#This Row],[Date of Call]])<=6, YEAR(calls[[#This Row],[Date of Call]]), YEAR(calls[[#This Row],[Date of Call]])+1) -> 2023 | I25: =TEXT(calls[[#This Row],[Date of Call]],"DDDD") -> Sunday | J25: {=_xlfn.IFS(calls[[#This Row],[Duration]]<=10,"Under 10 mins", calls[[#This Row],[Duration]]<=30, "10 to 30 mins", calls[[#This Row],[Duration]]<=60, "30 to 60 mins", calls[[#This Row],[Duration]]<=120, "1 to 2 hours", TRUE, "More than 2 hours")} -> 30 to 60 mins | K25: =ROUND(calls[[#This Row],[Satisfaction Rating]],0) -> 2
A26: Call_7295 | B26: C0010 | C26: 54 | D26: R01 | E26: 44934 | F26: 111 | G26: 3.3 | H26: =IF(MONTH(calls[[#This Row],[Date of Call]])<=6, YEAR(calls[[#This Row],[Date of Call]]), YEAR(calls[[#This Row],[Date of Call]])+1) -> 2023 | I26: =TEXT(calls[[#This Row],[Date of Call]],"DDDD") -> Sunday | J26: {=_xlfn.IFS(calls[[#This Row],[Duration]]<=10,"Under 10 mins", calls[[#This Row],[Duration]]<=30, "10 to 30 mins", calls[[#This Row],[Duration]]<=60, "30 to 60 mins", calls[[#This Row],[Duration]]<=120, "1 to 2 hours", TRUE, "More than 2 hours")} -> 30 to 60 mins | K26: =ROUND(calls[[#This Row],[Satisfaction Rating]],0) -> 3
A27: Call_7296 | B27: C0012 | C27: 28 | D27: R05 | E27: 44935 | F27: 63 | G27: 4.1 | H27: =IF(MONTH(calls[[#This Row],[Date of Call]])<=6, YEAR(calls[[#This Row],[Date of Call]]), YEAR(calls[[#This Row],[Date of Call]])+1) -> 2023 | I27: =TEXT(calls[[#This Row],[Date of Call]],"DDDD") -> Monday | J27: {=_xlfn.IFS(calls[[#This Row],[Duration]]<=10,"Under 10 mins", calls[[#This Row],[Duration]]<=30, "10 to 30 mins", calls[[#This Row],[Duration]]<=60, "30 to 60 mins", calls[[#This Row],[Duration]]<=120, "1 to 2 hours", TRUE, "More than 2 hours")} -> 10 to 30 mins | K27: =ROUND(calls[[#This Row],[Satisfaction Rating]],0) -> 4
A28: Call_7297 | B28: C0002 | C28: 73 | D28: R05 | E28: 44935 | F28: 80 | G28: 4.2 | H28: =IF(MONTH(calls[[#This Row],[Date of Call]])<=6, YEAR(calls[[#This Row],[Date of Call]]), YEAR(calls[[#This Row],[Date of Call]])+1) -> 2023 | I28: =TEXT(calls[[#This Row],[Date of Call]],"DDDD") -> Monday | J28: {=_xlfn.IFS(calls[[#This Row],[Duration]]<=10,"Under 10 mins", calls[[#This Row],[Duration]]<=30, "10 to 30 mins", calls[[#This Row],[Duration]]<=60, "30 to 60 mins", calls[[#This Row],[Duration]]<=120, "1 to 2 hours", TRUE, "More than 2 hours")} -> 1 to 2 hours | K28: =ROUND(calls[[#This Row],[Satisfaction Rating]],0) -> 4
... A1001: Call_8270 | B1001: C0009 | C1001: 114 | D1001: R01 | E1001: 45291 | F1001: 40 | G1001: 3.9 | H1001: =IF(MONTH(calls[[#This Row],[Date of Call]])<=6, YEAR(calls[[#This Row],[Date of Call]]), YEAR(calls[[#This Row],[Date of Call]])+1) -> 2024 | I1001: =TEXT(calls[[#This Row],[Date of Call]],"DDDD") -> Sunday | J1001: {=_xlfn.IFS(calls[[#This Row],[Duration]]<=10,"Under 10 mins", calls[[#This Row],[Duration]]<=30, "10 to 30 mins", calls[[#This Row],[Duration]]<=60, "30 to 60 mins", calls[[#This Row],[Duration]]<=120, "1 to 2 hours", TRUE, "More than 2 hours")} -> 1 to 2 hours | K1001: =ROUND(calls[[#This Row],[Satisfaction Rating]],0) -> 4
